<sdf version='1.11'>
  <model name='sam_bot' canonical_link='base_link'>
    <link name='base_link'>
      <must_be_base_link>true</must_be_base_link>
      <visual name='base_link_visual'>
        <geometry>
          <box>
            <size>0.41999999999999998 0.31 0.17999999999999999</size>
          </box>
        </geometry>
        <material>
          <ambient>0 1 1 1</ambient>
          <diffuse>0 1 1 1</diffuse>
        </material>
      </visual>
      <collision name='base_link_collision'>
        <geometry>
          <box>
            <size>0.41999999999999998 0.31 0.17999999999999999</size>
          </box>
        </geometry>
      </collision>
    </link>
    <link name='base_footprint'>
      <pose relative_to='base_joint'>0 0 0 0 0 0</pose>
      <inertial>
        <pose>0 0 0 1.5707963267948963 0 1.5707963267948963</pose>
        <mass>15</mass>
        <inertia>
          <ixx>0.26100000000000001</ixx>
          <ixy>0</ixy>
          <ixz>0</ixz>
          <iyy>0.34062499999999996</iyy>
          <iyz>0</iyz>
          <izz>0.16062500000000002</izz>
        </inertia>
      </inertial>
    </link>
    <joint name='base_joint' type='fixed'>
      <parent>base_link</parent>
      <child>base_footprint</child>
      <pose relative_to='base_link'>0 0 -0.15000000000000002 0 0 0</pose>
    </joint>
    <link name='drivewhl_l_link'>
      <pose relative_to='drivewhl_l_joint'>0 0 0 0 0 0</pose>
      <visual name='drivewhl_l_link_visual'>
        <pose relative_to='drivewhl_l_link'>0 0 0 1.5707963267948963 0 0</pose>
        <geometry>
          <cylinder>
            <radius>0.10000000000000001</radius>
            <length>0.040000000000000001</length>
          </cylinder>
        </geometry>
        <material>
          <ambient>0.300000012 0.300000012 0.300000012 1</ambient>
          <diffuse>0.699999988 0.699999988 0.699999988 1</diffuse>
        </material>
      </visual>
      <collision name='drivewhl_l_link_collision'>
        <pose relative_to='drivewhl_l_link'>0 0 0 1.5707963267948963 0 0</pose>
        <geometry>
          <cylinder>
            <radius>0.10000000000000001</radius>
            <length>0.040000000000000001</length>
          </cylinder>
        </geometry>
      </collision>
      <inertial>
        <pose>0 0 0 1.5707963267948963 0 0</pose>
        <mass>0.5</mass>
        <inertia>
          <ixx>0.0013166666666666667</ixx>
          <ixy>0</ixy>
          <ixz>0</ixz>
          <iyy>0.0013166666666666667</iyy>
          <iyz>0</iyz>
          <izz>0.0025000000000000005</izz>
        </inertia>
      </inertial>
    </link>
    <joint name='drivewhl_l_joint' type='continuous'>
      <parent>base_link</parent>
      <child>drivewhl_l_link</child>
      <pose relative_to='base_link'>-0.12 0.17999999999999999 -0.050000000000000003 0 0 0</pose>
      <axis>
        <xyz>0 1 0</xyz>
        <limit>
          <lower>-inf</lower>
          <upper>inf</upper>
        </limit>
      </axis>
    </joint>
    <link name='drivewhl_r_link'>
      <pose relative_to='drivewhl_r_joint'>0 0 0 0 0 0</pose>
      <visual name='drivewhl_r_link_visual'>
        <pose relative_to='drivewhl_r_link'>0 0 0 1.5707963267948963 0 0</pose>
        <geometry>
          <cylinder>
            <radius>0.10000000000000001</radius>
            <length>0.040000000000000001</length>
          </cylinder>
        </geometry>
        <material>
          <ambient>0.300000012 0.300000012 0.300000012 1</ambient>
          <diffuse>0.699999988 0.699999988 0.699999988 1</diffuse>
        </material>
      </visual>
      <collision name='drivewhl_r_link_collision'>
        <pose relative_to='drivewhl_r_link'>0 0 0 1.5707963267948963 0 0</pose>
        <geometry>
          <cylinder>
            <radius>0.10000000000000001</radius>
            <length>0.040000000000000001</length>
          </cylinder>
        </geometry>
      </collision>
      <inertial>
        <pose>0 0 0 1.5707963267948963 0 0</pose>
        <mass>0.5</mass>
        <inertia>
          <ixx>0.0013166666666666667</ixx>
          <ixy>0</ixy>
          <ixz>0</ixz>
          <iyy>0.0013166666666666667</iyy>
          <iyz>0</iyz>
          <izz>0.0025000000000000005</izz>
        </inertia>
      </inertial>
    </link>
    <joint name='drivewhl_r_joint' type='continuous'>
      <parent>base_link</parent>
      <child>drivewhl_r_link</child>
      <pose relative_to='base_link'>-0.12 -0.17999999999999999 -0.050000000000000003 0 0 0</pose>
      <axis>
        <xyz>0 1 0</xyz>
        <limit>
          <lower>-inf</lower>
          <upper>inf</upper>
        </limit>
      </axis>
    </joint>
    <link name='front_caster'>
      <pose relative_to='caster_joint'>0 0 0 0 0 0</pose>
      <visual name='front_caster_visual'>
        <geometry>
          <sphere>
            <radius>0.060000000000000026</radius>
          </sphere>
        </geometry>
        <material>
          <ambient>0 1 1 1</ambient>
          <diffuse>0 1 1 1</diffuse>
        </material>
      </visual>
      <collision name='front_caster_collision'>
        <geometry>
          <sphere>
            <radius>0.060000000000000026</radius>
          </sphere>
        </geometry>
        <surface>
          <friction>
            <ode>
              <mu>0.001</mu>
              <mu2>0.001</mu2>
            </ode>
          </friction>
        </surface>
      </collision>
      <inertial>
        <mass>0.5</mass>
        <inertia>
          <ixx>0.00072000000000000059</ixx>
          <ixy>0</ixy>
          <ixz>0</ixz>
          <iyy>0.00072000000000000059</iyy>
          <iyz>0</iyz>
          <izz>0.00072000000000000059</izz>
        </inertia>
      </inertial>
    </link>
    <joint name='caster_joint' type='fixed'>
      <parent>base_link</parent>
      <child>front_caster</child>
      <pose relative_to='base_link'>0.14000000000000001 0 -0.089999999999999997 0 0 0</pose>
    </joint>

    <joint name='imu_joint' type='fixed'>
      <parent>base_link</parent>
      <child>imu_link</child>
      <pose relative_to="base_link">0.0 0.0 0.01 0 0 0</pose>
    </joint>

    <link name='imu_link'>
      <pose relative_to="imu_joint"/>
      <visual name="imu_link_visual">
        <geometry>
          <box><size>
            0.1 0.1 0.1
          </size></box>
        </geometry>
      </visual>

      <collision name="imu_link_collision">
        <geometry>
          <box><size>
            0.1 0.1 0.1
          </size></box>
        </geometry>
      </collision>

      <xacro:box_inertia m="0.1" w="0.1" d="0.1" h="0.1"/>

      <sensor name="imu_sensor" type="imu">
        <always_on>true</always_on>
        <update_rate>100</update_rate>
        <visualize>true</visualize>
        <topic>demo/imu</topic>
        <gz_frame_id>imu_link</gz_frame_id>
        <imu>
          <angular_velocity>
            <x>
              <noise type="gaussian">
                <mean>0.0</mean>
                <stddev>2e-4</stddev>
                <bias_mean>0.0000075</bias_mean>
                <bias_stddev>0.0000008</bias_stddev>
              </noise>
            </x>
            <y>
              <noise type="gaussian">
                <mean>0.0</mean>
                <stddev>2e-4</stddev>
                <bias_mean>0.0000075</bias_mean>
                <bias_stddev>0.0000008</bias_stddev>
              </noise>
            </y>
            <z>
              <noise type="gaussian">
                <mean>0.0</mean>
                <stddev>2e-4</stddev>
                <bias_mean>0.0000075</bias_mean>
                <bias_stddev>0.0000008</bias_stddev>
              </noise>
            </z>
          </angular_velocity>
          <linear_acceleration>
            <x>
              <noise type="gaussian">
                <mean>0.0</mean>
                <stddev>1.7e-2</stddev>
                <bias_mean>0.1</bias_mean>
                <bias_stddev>0.001</bias_stddev>
              </noise>
            </x>
            <y>
              <noise type="gaussian">
                <mean>0.0</mean>
                <stddev>1.7e-2</stddev>
                <bias_mean>0.1</bias_mean>
                <bias_stddev>0.001</bias_stddev>
              </noise>
            </y>
            <z>
              <noise type="gaussian">
                <mean>0.0</mean>
                <stddev>1.7e-2</stddev>
                <bias_mean>0.1</bias_mean>
                <bias_stddev>0.001</bias_stddev>
              </noise>
            </z>
          </linear_acceleration>
        </imu>
      </sensor>
    </link>

    <plugin name='gz::sim::systems::DiffDrive' filename='gz-sim-diff-drive-system'>
      <left_joint>drivewhl_l_joint</left_joint>
      <right_joint>drivewhl_r_joint</right_joint>
      <wheel_separation>0.4</wheel_separation>
      <wheel_radius>0.1</wheel_radius>
      <max_linear_acceleration>0.1</max_linear_acceleration>
      <topic>/demo/cmd_vel</topic>
      <odom_topic>/demo/odom</odom_topic>
      <tf_topic>/tf</tf_topic>
      <frame_id>odom</frame_id>
      <child_frame_id>base_link</child_frame_id>
      <use_sim_time>true</use_sim_time>
    </plugin>
    <plugin name='gz::sim::systems::JointStatePublisher' filename='gz-sim-joint-state-publisher-system'>
      <topic>joint_states</topic>
      <use_sim_time>true</use_sim_time>
    </plugin>
    <joint name='lidar_joint' type='fixed'>
      <parent>base_link</parent>
      <child>lidar_link</child>
      <pose relative_to='base_link'>0 0 0.12 0 0 0</pose>
    </joint>
    <link name='lidar_link'>
      <pose relative_to='lidar_joint'>0 0 0 0 0 0</pose>
      <visual name='lidar_link_visual'>
        <geometry>
          <cylinder>
            <radius>0.050799999999999998</radius>
            <length>0.055</length>
          </cylinder>
        </geometry>
      </visual>
      <collision name='lidar_link_collision'>
        <geometry>
          <cylinder>
            <radius>0.050799999999999998</radius>
            <length>0.055</length>
          </cylinder>
        </geometry>
      </collision>
      <inertial>
        <pose>0 0 0 1.5707963267948963 0 0</pose>
        <mass>0.125</mass>
        <inertia>
          <ixx>0.00011215541666666665</ixx>
          <ixy>0</ixy>
          <ixz>0</ixz>
          <iyy>0.00011215541666666665</iyy>
          <iyz>0</iyz>
          <izz>0.00016129</izz>
        </inertia>
      </inertial>
      <sensor name='lidar' type='gpu_lidar'>
        <always_on>true</always_on>
        <visualize>true</visualize>
        <update_rate>5</update_rate>
        <topic>scan</topic>
        <lidar>
          <scan>
            <horizontal>
              <samples>360</samples>
              <resolution>1</resolution>
              <min_angle>0</min_angle>
              <max_angle>6.2800000000000002</max_angle>
            </horizontal>
          </scan>
          <range>
            <min>0.12</min>
            <max>3.5</max>
            <resolution>0.014999999999999999</resolution>
          </range>
          <noise>
            <type>gaussian</type>
            <mean>0</mean>
            <stddev>0.01</stddev>
          </noise>
        </lidar>
        <gz_frame_id>lidar_link</gz_frame_id>
      </sensor>
    </link>
    <joint name='camera_joint' type='fixed'>
      <parent>base_link</parent>
      <child>camera_link</child>
      <pose relative_to='base_link'>0.215 0 0.050000000000000003 0 0 0</pose>
    </joint>
    <link name='camera_link'>
      <pose relative_to='camera_joint'>0 0 0 0 0 0</pose>
      <visual name='camera_link_visual'>
        <geometry>
          <box>
            <size>0.014999999999999999 0.13 0.022200000000000001</size>
          </box>
        </geometry>
      </visual>
      <collision name='camera_link_collision'>
        <geometry>
          <box>
            <size>0.014999999999999999 0.13 0.022200000000000001</size>
          </box>
        </geometry>
      </collision>
      <inertial>
        <pose>0 0 0 1.5707963267948963 0 1.5707963267948963</pose>
        <mass>0.035000000000000003</mass>
        <inertia>
          <ixx>5.0729116666666679e-05</ixx>
          <ixy>0</ixy>
          <ixz>0</ixz>
          <iyy>4.9947916666666673e-05</iyy>
          <iyz>0</iyz>
          <izz>2.0937e-06</izz>
        </inertia>
      </inertial>
      <sensor name='depth_camera' type='rgbd_camera'>
        <always_on>true</always_on>
        <visualize>true</visualize>
        <update_rate>5</update_rate>
        <topic>depth_camera</topic>
        <camera>
          <horizontal_fov>1.0471980000000001</horizontal_fov>
          <image>
            <width>640</width>
            <height>480</height>
          </image>
          <clip>
            <near>0.050000000000000003</near>
            <far>3</far>
          </clip>
        </camera>
        <gz_frame_id>camera_link</gz_frame_id>
        <baseline>0.2</baseline>
        <pointCloudCutoff>0.5</pointCloudCutoff>
        <pointCloudCutoffMax>3.0</pointCloudCutoffMax>
        <distortionK1>0</distortionK1>
        <distortionK2>0</distortionK2>
        <distortionK3>0</distortionK3>
        <distortionT1>0</distortionT1>
        <distortionT2>0</distortionT2>
        <CxPrime>0</CxPrime>
        <Cx>0</Cx>
        <Cy>0</Cy>
        <focalLength>0</focalLength>
        <hackBaseline>0</hackBaseline>
      </sensor>
    </link>
  </model>
</sdf>
